Workbook

Sheet Read Me
A1: UK TikTok Shop lead list – shops doing £10K–£30K
A3: Source: FastMoss MCP, monthly shop rankings for TikTok Shop UK (region GB), period = September 2026 (latest completed month; closest available to "last 28 days").
A4: Pulled: 8 Oct 2026. All money values are GBP as reported by FastMoss.
A6: How it was built
A7: • FastMoss has no GMV-range filter, and each ranking stops at 500 shops. The overall UK ranking bottoms out at ~£36K, so £10–30K shops only appear inside category rankings.
A8: • One ranking page (10 shops) was pulled per category at the depth where GMV falls into £10–30K. Only shops inside the band were kept.
A9: • This is a SAMPLE of each category's band, not every shop in it: the free trial allows ~100 credits/day and 1 page = 1 credit.
A11: Important caveat on GMV
A12: • "Sep-26 GMV in category" is the shop's sales WITHIN that category, not its total. Shops that sell across categories can be bigger overall.
A13: • Band confidence: High = ranked in its own main category; Medium = ranked outside its main category; Low = we saw evidence it is above £30K in total.
A14: • "UK overall rank (Sep)" is a useful cross-check: UK rank 500 ≈ £36K/month, so ranks well above ~700 are consistent with the band.
A16: Profile columns (TikTok handle → UK overall rank) were filled for 54 UK-based shops, chosen to cover every category. The rest are blank to save credits.
... A19: Not covered yet: Shoes, Luggage & Bags and Furniture (band is deeper than the page checked); Books and other small categories were not probed.

Sheet UK Leads
A1: Category (ranked in) | B1: Shop name | C1: Company / legal name | D1: Main category | E1: Shop type | F1: Sep-26 GMV in category (£) | G1: Units sold | H1: GMV MoM growth | I1: Units MoM growth | J1: Affiliate creators (Sep) | K1: Products with sales | L1: Active products | M1: Shop rating | N1: Band confidence | O1: Notes | P1: TikTok handle | Q1: TikTok profile URL | R1: TikTok followers | S1: TikTok videos | T1: Shop created | U1: All-time GMV (£) | V1: All-time units | W1: Total products listed | X1: All-time affiliate creators | Y1: All-time videos | Z1: All-time lives | AA1: Min price (£) | AB1: Max price (£) | AC1: Avg price (£) | AD1: Delivery rate | AE1: Positive feedback | AF1: Response rate | AG1: Category rank (Sep) | AH1: UK overall rank (Sep) | AI1: Seller ID
A2: Automotive & Motorcycle | B2: Joytutus GB | C2: GuangZhouZaoZhongWanDianZiShangWuYouXianGongSi | D2: Automotive & Motorcycle | E2: Cross-border | F2: 23492.68 | G2: 1552 | H2: -0.0427 | I2: -0.2821 | J2: 241 | K2: 37 | L2: 63 | M2: 4.2 | N2: High | AI2: 8647193604911503559
A3: Automotive & Motorcycle | B3: HAUDIO Global | D3: Automotive & Motorcycle | E3: Cross-border | F3: 21804.76 | G3: 341 | H3: 0.472 | I3: 0.2222 | J3: 52 | K3: 9 | L3: 24 | M3: 3.5 | N3: High | AI3: 8647509933899094535
A4: Automotive & Motorcycle | B4: TIDY MONSTER UK | D4: Home Supplies | E4: UK local | F4: 19758.12 | G4: 1268 | H4: 1.2384 | I4: 0.7759 | J4: 34 | K4: 1 | L4: 16 | M4: 4.4 | N4: Medium – may sell in other categories | AI4: 7496062834106337441
A5: Automotive & Motorcycle | B5: rose origins shop | C5: MODAMAYSTATION LTD | D5: Home Supplies | E5: UK local | F5: 19459.44 | G5: 897 | H5: 0.2425 | I5: -0.2731 | J5: 14 | K5: 8 | L5: 42 | M5: 3.7 | N5: Medium – may sell in other categories | AI5: 7496079384673160186
A6: Automotive & Motorcycle | B6: Hieom One | D6: Automotive & Motorcycle | E6: UK local | F6: 18796.42 | G6: 1054 | H6: -0.702 | I6: -0.7104 | J6: 57 | K6: 11 | L6: 121 | M6: 3.4 | N6: High | P6: zmgh49shop | Q6: https://www.tiktok.com/@zmgh49shop | R6: 1965 | S6: 295 | T6: 2025-10-10 | U6: 1361989.5 | V6: 104192 | W6: 240 | X6: 1703 | Y6: 4716 | Z6: 846 | AA6: 1.14 | AB6: 50 | AC6: 8.88 | AD6: 0.81 | AE6: 0.74 | AF6: 1 | AG6: 20 | AH6: 1321 | AI6: 7494129241962152989
A7: Automotive & Motorcycle | B7: Easy Trading | C7: Shenzhen Heyu Technology Co., Ltd. | D7: Automotive & Motorcycle | E7: Cross-border | F7: 18648.68 | G7: 1586 | H7: -0.4186 | I7: -0.4338 | J7: 151 | K7: 38 | L7: 110 | M7: 2.7 | N7: High | AI7: 7495159456203376895
A8: Automotive & Motorcycle | B8: Sisocor | C8: Sisocor | D8: Automotive & Motorcycle | E8: UK local | F8: 17727.45 | G8: 1384 | H8: -0.4278 | I8: -0.4466 | J8: 286 | K8: 1 | L8: 14 | M8: 4.7 | N8: High | P8: sisuocor | Q8: https://www.tiktok.com/@sisuocor | R8: 2324 | S8: 232 | T8: 2024-10-23 | U8: 480990.87 | V8: 51236 | W8: 117 | X8: 864 | Y8: 2436 | Z8: 927 | AA8: 0.77 | AB8: 55 | AC8: 10.2 | AD8: 0.69 | AE8: 0.88 | AF8: 0.98 | AG8: 34 | AH8: 2065 | AI8: 7495918070877490097
A9: Automotive & Motorcycle | B9: Yass Clean | C9: Yass Clean Ltd | D9: Home Supplies | E9: UK local | F9: 17622.47 | G9: 610 | H9: -0.0634 | I9: -0.1223 | J9: 30 | K9: 1 | L9: 35 | M9: 4.6 | N9: Medium – may sell in other categories | AI9: 7495888481436796939
A10: Baby & Maternity | B10: Yolk Baby Store | C10: Pujiang County Furui Electronic Commerce Co., Ltd. | D10: Baby & Maternity | E10: Cross-border | F10: 21072.67 | G10: 2545 | H10: 0.3437 | I10: 0.2241 | J10: 420 | K10: 252 | L10: 773 | M10: 4.9 | N10: High | AI10: 7495563545389467829
A11: Baby & Maternity | B11: Bravellous Clothing | C11: Shenzhen Jinxingsheng Apparel Co., Ltd. | D11: Baby & Maternity | E11: Cross-border | F11: 21040.77 | G11: 1299 | H11: 0.0846 | I11: -0.0069 | J11: 54 | K11: 40 | L11: 110 | M11: 4.6 | N11: High | AI11: 7495287627779574005
A12: Baby & Maternity | B12: Zimpli Kids | C12: ZIMPLI KIDS LIMITED | D12: Beauty & Personal Care | E12: UK local | F12: 20720.29 | G12: 1512 | H12: 1.1935 | I12: 1.2203 | J12: 488 | K12: 28 | L12: 129 | M12: 4.4 | N12: Medium – may sell in other categories | AI12: 7495235322873678296
A13: Baby & Maternity | B13: BooBoo Baby Products | C13: IPUK Limited | D13: Baby & Maternity | E13: UK local | F13: 20468.88 | G13: 296 | H13: 0.1889 | I13: 0.1255 | J13: 108 | K13: 14 | L13: 25 | M13: 4.1 | N13: High | P13: booboobabyproducts.com | Q13: https://www.tiktok.com/@booboobabyproducts.com | R13: 2077 | S13: 120 | T13: 2024-08-31 | U13: 234890.89 | V13: 3967 | W13: 32 | X13: 477 | Y13: 923 | Z13: 180 | AA13: 4.98 | AB13: 112.64 | AC13: 64.11 | AD13: 0.67 | AE13: 0.88 | AF13: 1 | AG13: 39 | AH13: 2193 | AI13: 7495881815561832964
A14: Baby & Maternity | B14: Parents & Peanuts | D14: Baby & Maternity | E14: UK local | F14: 20262.29 | G14: 116 | H14: -0.0717 | I14: -0.1888 | J14: 29 | K14: 13 | L14: 14 | M14: 4.3 | N14: High | AI14: 7496010701964413451
A15: Baby & Maternity | B15: TRENDY HOUSEHOLDS | C15: HOUSEHOLD TRENDS LTD | D15: Baby & Maternity | E15: UK local | F15: 20184.53 | G15: 1286 | H15: 1.2264 | I15: 1.3727 | J15: 0 | K15: 7 | L15: 44 | M15: 4.6 | N15: High | AI15: 7496092059839465742
A16: Baby & Maternity | B16: LADIDA UK | C16: LADIDA (UK) BABY TOYS COMPANY LIMITED | D16: Baby & Maternity | E16: UK local | F16: 19801.14 | G16: 345 | H16: 0.0838 | I16: -0.1062 | J16: 138 | K16: 38 | L16: 65 | M16: 3.8 | N16: High | P16: ladidatoystore | Q16: https://www.tiktok.com/@ladidatoystore | R16: 1552 | S16: 355 | T16: 2024-02-25 | U16: 261110.58 | V16: 7540 | W16: 99 | X16: 878 | Y16: 1524 | Z16: 370 | AA16: 2.63 | AB16: 114.65 | AC16: 36.57 | AD16: 0.76 | AE16: 0.87 | AF16: 1 | AG16: 36 | AH16: 2152 | AI16: 7495599747723463227
A17: Baby & Maternity | B17: lifeideas | C17: LAI BEAUTIFUL LTD | D17: Home Supplies | E17: UK local | F17: 19036.98 | G17: 934 | H17: 2.8139 | I17: 3.3241 | J17: 45 | K17: 26 | L17: 3152 | M17: 4 | N17: Low – likely above £30K | O17: Also £19.9K in Kitchenware ranking → combined ≈ £39.0K | AI17: 7495530049968704292
A18: Baby & Maternity | B18: My Expert Midwife | C18: CHRISTMAS ANGELS LIMITED | D18: Baby & Maternity | E18: UK local | F18: 18961.4 | G18: 411 | H18: 1.1644 | I18: 0.9855 | J18: 261 | K18: 11 | L18: 19 | M18: 4.3 | N18: High | P18: my_expertmidwife | Q18: https://www.tiktok.com/@my_expertmidwife | R18: 96364 | S18: 618 | T18: 2023-12-19 | U18: 69954.25 | V18: 3550 | W18: 83 | X18: 625 | Y18: 1266 | Z18: 69 | AA18: 2.4 | AB18: 253.5 | AC18: 19.8 | AD18: 0.73 | AE18: 0.97 | AF18: 1 | AG18: 28 | AH18: 1935 | AI18: 7495123108008462645
A19: Baby & Maternity | B19: Baby Toys Stop | C19: Dongguan Mingjia Trading Co., Ltd. | D19: Baby & Maternity | E19: Cross-border | F19: 18900.14 | G19: 2342 | H19: 0.8616 | I19: 0.8441 | J19: 109 | K19: 9 | L19: 9 | M19: 4.8 | N19: High | AI19: 7495160888994269822
A20: Beauty & Personal Care | B20: Sculpted by Aimee | C20: Sculpted by Aimee uk Ltd | D20: Beauty & Personal Care | E20: UK local | F20: 26104.16 | G20: 895 | H20: -0.5544 | I20: -0.6368 | J20: 854 | K20: 35 | L20: 93 | M20: 3.5 | N20: Low – likely above £30K | O20: Verified shop-wide last-28-day GMV = £33,617 (56.9% product card, 43.1% affiliate) | P20: sculptedbyaimeestore | Q20: https://www.tiktok.com/@sculptedbyaimeestore | R20: 18674 | S20: 289 | T20: 2023-12-15 | U20: 831268.17 | V20: 41459 | W20: 146 | X20: 4277 | Y20: 9003 | Z20: 1818 | AA20: 4.8 | AB20: 83 | AC20: 22.52 | AD20: 0.62 | AE20: 0.94 | AF20: 0.84 | AG20: 294 | AH20: 1709 | AI20: 7495320015950547394
A21: Beauty & Personal Care | B21: BLOOMMIX | D21: Beauty & Personal Care | E21: UK local | F21: 24099.73 | G21: 1287 | H21: 3.1523 | I21: 1.9518 | J21: 154 | K21: 4 | L21: 8 | M21: 4.4 | N21: High | P21: poppys332 | Q21: https://www.tiktok.com/@poppys332 | R21: 33 | S21: 82 | T21: 2025-09-27 | U21: 149779.49 | V21: 10650 | W21: 37 | X21: 1211 | Y21: 2447 | Z21: 155 | AA21: 3 | AB21: 95 | AC21: 8.11 | AD21: 0.7 | AE21: 0.72 | AF21: 1 | AG21: 236 | AH21: 1324 | AI21: 7496303388086864432
A22: Beauty & Personal Care | B22: LACTOmedi | D22: Beauty & Personal Care | E22: UK local | F22: 23896.57 | G22: 1370 | H22: 1.3801 | I22: 0.7452 | J22: 800 | K22: 7 | L22: 8 | M22: 4.4 | N22: High | O22: No linked TikTok brand account found | T22: 2026-05-16 | U22: 38863.2 | V22: 3063 | W22: 8 | X22: 1075 | Y22: 2331 | Z22: 121 | AA22: 7.79 | AB22: 76.25 | AG22: 317 | AH22: 1925 | AI22: 7494644199581058663
A23: Beauty & Personal Care | B23: NOVO OVO Nails | C23: Novo Ovo Shenzhen Cosmetics Co.,Ltd. | D23: Beauty & Personal Care | E23: Cross-border | F23: 23872.6 | G23: 1704 | H23: -0.2842 | I23: -0.4081 | J23: 1240 | K23: 39 | L23: 93 | M23: 4.7 | N23: High | AI23: 7496099128061299639
A24: Beauty & Personal Care | B24: sofragrance | C24: INCOS LIMITED | D24: Beauty & Personal Care | E24: UK local | F24: 23770.07 | G24: 2677 | H24: 0.6142 | I24: 0.3972 | J24: 80 | K24: 39 | L24: 35 | M24: 3.7 | N24: High | AI24: 7495827636321422087
A25: Beauty & Personal Care | B25: gzolimy cosmetics | C25: Guangzhou Aolimei Cosmetics Co., Ltd. | D25: Beauty & Personal Care | E25: Cross-border | F25: 23760.35 | G25: 5877 | H25: -0.18 | I25: -0.1827 | J25: 411 | K25: 90 | L25: 91 | M25: 4.7 | N25: High | AI25: 7495975730098637639
A26: Beauty & Personal Care | B26: Weekeinght | D26: Kitchenware | E26: UK local | F26: 23677.11 | G26: 1604 | H26: -0.3777 | I26: -0.3859 | J26: 143 | K26: 16 | L26: 98 | M26: 3.6 | N26: Low – likely above £30K | O26: Also £23.1K in Automotive ranking → combined ≈ £46.8K | AI26: 7494686896434349919
A27: Beauty & Personal Care | B27: GAOYU STAR | C27: SHENZHEN GAOYU STAR TRADING CO LTD | D27: Beauty & Personal Care | E27: UK local | F27: 23591.27 | G27: 924 | H27: -0.3387 | I27: -0.464 | J27: 184 | K27: 6 | L27: 49 | M27: 4 | N27: Low – likely above £30K | O27: Also £22.6K in Home Improvement ranking → combined ≈ £46.2K | AI27: 7494991028040600241
A28: Beauty & Personal Care | B28: TONVVD | C28: Shenzhen Maiwode Technology Co., Ltd. | D28: Beauty & Personal Care | E28: Cross-border | F28: 23490.46 | G28: 4061 | H28: 0.2824 | I28: 0.1321 | J28: 480 | K28: 174 | L28: 351 | M28: 4.6 | N28: High | AI28: 7495161267940658045
A29: Beauty & Personal Care | B29: WALKTOTOP | C29: WALKTOTOP CREATIVE LTD | D29: Home Supplies | E29: UK local | F29: 22832.68 | G29: 1280 | H29: 0.4714 | I29: 0.3646 | J29: 81 | K29: 9 | L29: 49 | M29: 4 | N29: Medium – may sell in other categories | AI29: 7496120993122912978
A30: Beauty & Personal Care | B30: houseofamoruk | C30: houseofamoruk | D30: Beauty & Personal Care | E30: UK local | F30: 22693.36 | G30: 1206 | H30: -0.3809 | I30: -0.4647 | J30: 1082 | K30: 81 | L30: 240 | M30: 3.9 | N30: High | P30: houseofamoruk | Q30: https://www.tiktok.com/@houseofamoruk | R30: 149555 | S30: 5076 | T30: 2022-06-26 | U30: 806078.78 | V30: 62362 | W30: 556 | X30: 1530 | Y30: 3071 | Z30: 654 | AA30: 2.99 | AB30: 169.99 | AC30: 14.44 | AD30: 0.76 | AE30: 0.92 | AF30: 0.96 | AG30: 312 | AH30: 1876 | AI30: 7494557294615235116
A31: Beauty & Personal Care | B31: Excellent home appli | C31: Pingyang County Leixing Crafts Trading Firm | D31: Beauty & Personal Care | E31: Cross-border | F31: 21151.78 | G31: 904 | H31: 18.0385 | I31: 17.8333 | J31: 22 | K31: 5 | L31: 23 | M31: 3.7 | N31: High | AI31: 7495625978765674959
A32: Beauty & Personal Care | B32: Zoistar | D32: Fashion Accessories | E32: Cross-border | F32: 12454.15 | G32: 908 | H32: -0.2428 | I32: -0.0668 | J32: 19 | K32: 4 | L32: 119 | M32: 4.2 | N32: Medium – may sell in other categories | AI32: 7494619105434174471
A33: Collectibles | B33: ACE HITS TCG LTD | D33: Collectibles | E33: UK local | F33: 28832.46 | G33: 1860 | H33: -0.277 | I33: -0.3643 | J33: 1379 | K33: 52 | L33: 67 | M33: 4.6 | N33: High | P33: acehitstcg | Q33: https://www.tiktok.com/@acehitstcg | R33: 9091 | S33: 307 | T33: 2025-10-10 | U33: 560773.91 | V33: 39376 | W33: 264 | X33: 2 | Y33: 30 | Z33: 453 | AA33: 0.99 | AB33: 482.09 | AC33: 12.27 | AD33: 0.86 | AE33: 1 | AF33: 0.75 | AG33: 42 | AH33: 1676 | AI33: 7494185371692270821
A34: Collectibles | B34: Spens Pokestop | C34: TOP G'S LIMITED | D34: Collectibles | E34: UK local | F34: 27136.58 | G34: 2745 | H34: -0.3119 | I34: -0.3517 | J34: 108 | K34: 15 | L34: 15 | M34: 4.9 | N34: High | AI34: 7494751408113355675
A35: Collectibles | B35: BMJBREAKS | D35: Collectibles | E35: UK local | F35: 26674.99 | G35: 269 | H35: 72.9349 | I35: 9.3462 | J35: 94 | K35: 20 | L35: 4 | M35: 4.3 | N35: High | AI35: 7494638880325141702
A36: Collectibles | B36: TCHewy Collectables | C36: TCHewy Collectables | D36: Collectibles | E36: UK local | F36: 25711.72 | G36: 462 | H36: -0.0363 | I36: -0.352 | J36: 239 | K36: 12 | L36: 21 | M36: 4.6 | N36: High | AI36: 7494665262943013477
A37: Collectibles | B37: SportsMemorabilia.co.uk | D37: Collectibles | E37: UK local | F37: 25181.99 | G37: 347 | H37: -0.3614 | I37: -0.0467 | J37: 126 | K37: 19 | L37: 13 | M37: 4.8 | N37: High | AI37: 7496312090293537514
A38: Collectibles | B38: Wiggyscollectables | C38: Wiggyscollectables | D38: Collectibles | E38: UK local | F38: 24750.47 | G38: 1441 | H38: -0.3806 | I38: -0.3184 | J38: 1987 | K38: 79 | L38: 146 | M38: 4.7 | N38: High | P38: wiggyscollectables | Q38: https://www.tiktok.com/@wiggyscollectables | R38: 34625 | S38: 291 | T38: 2023-07-20 | U38: 2625518.8 | V38: 187799 | W38: 550 | X38: 1 | Y38: 93 | Z38: 523 | AA38: 1 | AB38: 1369.99 | AC38: 25.41 | AD38: 0.92 | AE38: 1 | AF38: 1 | AG38: 41 | AH38: 1658 | AI38: 7494801336240933390
A39: Collectibles | B39: PrestinePalaceTCG | C39: PrestinePalaceTCG | D39: Collectibles | E39: UK local | F39: 24071.35 | G39: 750 | H39: 0.7263 | I39: 0.4911 | J39: 32 | K39: 6 | L39: 20 | M39: 4.2 | N39: High | AI39: 7494666354480155165
A40: Collectibles | B40: Monster TCG | D40: Collectibles | E40: UK local | F40: 23801.37 | G40: 740 | H40: 8.9413 | I40: 5.0656 | J40: 259 | K40: 27 | L40: 46 | M40: 4.8 | N40: High | AI40: 7494764502796895239
...

Sheet Category Summary
A1: Category | B1: Leads found | C1: High confidence | D1: With TikTok profile data | E1: Avg Sep GMV in category (£) | F1: Rows searched (ranking page)
A2: Automotive & Motorcycle | B2: =COUNTIF('UK Leads'!$A$2:$A$203,A2) -> 8 | C2: =COUNTIFS('UK Leads'!$A$2:$A$203,A2,'UK Leads'!$N$2:$N$203,"High") -> 5 | D2: =COUNTIFS('UK Leads'!$A$2:$A$203,A2,'UK Leads'!$P$2:$P$203,"<>") -> 2 | E2: =AVERAGEIF('UK Leads'!$A$2:$A$203,A2,'UK Leads'!$F$2:$F$203) -> 19663.752 | F2: p4
A3: Baby & Maternity | B3: =COUNTIF('UK Leads'!$A$2:$A$203,A3) -> 10 | C3: =COUNTIFS('UK Leads'!$A$2:$A$203,A3,'UK Leads'!$N$2:$N$203,"High") -> 8 | D3: =COUNTIFS('UK Leads'!$A$2:$A$203,A3,'UK Leads'!$P$2:$P$203,"<>") -> 3 | E3: =AVERAGEIF('UK Leads'!$A$2:$A$203,A3,'UK Leads'!$F$2:$F$203) -> 20044.909 | F3: p4
A4: Beauty & Personal Care | B4: =COUNTIF('UK Leads'!$A$2:$A$203,A4) -> 13 | C4: =COUNTIFS('UK Leads'!$A$2:$A$203,A4,'UK Leads'!$N$2:$N$203,"High") -> 8 | D4: =COUNTIFS('UK Leads'!$A$2:$A$203,A4,'UK Leads'!$P$2:$P$203,"<>") -> 3 | E4: =AVERAGEIF('UK Leads'!$A$2:$A$203,A4,'UK Leads'!$F$2:$F$203) -> 22722.638 | F4: p30 (+p50 units-sorted)
A5: Collectibles | B5: =COUNTIF('UK Leads'!$A$2:$A$203,A5) -> 10 | C5: =COUNTIFS('UK Leads'!$A$2:$A$203,A5,'UK Leads'!$N$2:$N$203,"High") -> 10 | D5: =COUNTIFS('UK Leads'!$A$2:$A$203,A5,'UK Leads'!$P$2:$P$203,"<>") -> 2 | E5: =AVERAGEIF('UK Leads'!$A$2:$A$203,A5,'UK Leads'!$F$2:$F$203) -> 25242.337 | F5: p5
A6: Computers & Office Equipment | B6: =COUNTIF('UK Leads'!$A$2:$A$203,A6) -> 4 | C6: =COUNTIFS('UK Leads'!$A$2:$A$203,A6,'UK Leads'!$N$2:$N$203,"High") -> 3 | D6: =COUNTIFS('UK Leads'!$A$2:$A$203,A6,'UK Leads'!$P$2:$P$203,"<>") -> 1 | E6: =AVERAGEIF('UK Leads'!$A$2:$A$203,A6,'UK Leads'!$F$2:$F$203) -> 26612.013 | F6: p2
A7: Fashion Accessories | B7: =COUNTIF('UK Leads'!$A$2:$A$203,A7) -> 10 | C7: =COUNTIFS('UK Leads'!$A$2:$A$203,A7,'UK Leads'!$N$2:$N$203,"High") -> 10 | D7: =COUNTIFS('UK Leads'!$A$2:$A$203,A7,'UK Leads'!$P$2:$P$203,"<>") -> 2 | E7: =AVERAGEIF('UK Leads'!$A$2:$A$203,A7,'UK Leads'!$F$2:$F$203) -> 18329.787 | F7: p8
A8: Food & Beverages | B8: =COUNTIF('UK Leads'!$A$2:$A$203,A8) -> 10 | C8: =COUNTIFS('UK Leads'!$A$2:$A$203,A8,'UK Leads'!$N$2:$N$203,"High") -> 10 | D8: =COUNTIFS('UK Leads'!$A$2:$A$203,A8,'UK Leads'!$P$2:$P$203,"<>") -> 3 | E8: =AVERAGEIF('UK Leads'!$A$2:$A$203,A8,'UK Leads'!$F$2:$F$203) -> 18314.298 | F8: p10
A9: Health | B9: =COUNTIF('UK Leads'!$A$2:$A$203,A9) -> 10 | C9: =COUNTIFS('UK Leads'!$A$2:$A$203,A9,'UK Leads'!$N$2:$N$203,"High") -> 10 | D9: =COUNTIFS('UK Leads'!$A$2:$A$203,A9,'UK Leads'!$P$2:$P$203,"<>") -> 3 | E9: =AVERAGEIF('UK Leads'!$A$2:$A$203,A9,'UK Leads'!$F$2:$F$203) -> 16079.697 | F9: p12
A10: Home Improvement | B10: =COUNTIF('UK Leads'!$A$2:$A$203,A10) -> 8 | C10: =COUNTIFS('UK Leads'!$A$2:$A$203,A10,'UK Leads'!$N$2:$N$203,"High") -> 7 | D10: =COUNTIFS('UK Leads'!$A$2:$A$203,A10,'UK Leads'!$P$2:$P$203,"<>") -> 3 | E10: =AVERAGEIF('UK Leads'!$A$2:$A$203,A10,'UK Leads'!$F$2:$F$203) -> 21635.394 | F10: p6
A11: Home Supplies | B11: =COUNTIF('UK Leads'!$A$2:$A$203,A11) -> 11 | C11: =COUNTIFS('UK Leads'!$A$2:$A$203,A11,'UK Leads'!$N$2:$N$203,"High") -> 8 | D11: =COUNTIFS('UK Leads'!$A$2:$A$203,A11,'UK Leads'!$P$2:$P$203,"<>") -> 3 | E11: =AVERAGEIF('UK Leads'!$A$2:$A$203,A11,'UK Leads'!$F$2:$F$203) -> 19759 | F11: p15 (+p50 units-sorted)
A12: Household Appliances | B12: =COUNTIF('UK Leads'!$A$2:$A$203,A12) -> 9 | C12: =COUNTIFS('UK Leads'!$A$2:$A$203,A12,'UK Leads'!$N$2:$N$203,"High") -> 5 | D12: =COUNTIFS('UK Leads'!$A$2:$A$203,A12,'UK Leads'!$P$2:$P$203,"<>") -> 2 | E12: =AVERAGEIF('UK Leads'!$A$2:$A$203,A12,'UK Leads'!$F$2:$F$203) -> 12408.89 | F12: p12
A13: Kids' Fashion | B13: =COUNTIF('UK Leads'!$A$2:$A$203,A13) -> 10 | C13: =COUNTIFS('UK Leads'!$A$2:$A$203,A13,'UK Leads'!$N$2:$N$203,"High") -> 7 | D13: =COUNTIFS('UK Leads'!$A$2:$A$203,A13,'UK Leads'!$P$2:$P$203,"<>") -> 2 | E13: =AVERAGEIF('UK Leads'!$A$2:$A$203,A13,'UK Leads'!$F$2:$F$203) -> 15190.315 | F13: p3
... A23: Womenswear & Underwear | B23: =COUNTIF('UK Leads'!$A$2:$A$203,A23) -> 8 | C23: =COUNTIFS('UK Leads'!$A$2:$A$203,A23,'UK Leads'!$N$2:$N$203,"High") -> 8 | D23: =COUNTIFS('UK Leads'!$A$2:$A$203,A23,'UK Leads'!$P$2:$P$203,"<>") -> 1 | E23: =AVERAGEIF('UK Leads'!$A$2:$A$203,A23,'UK Leads'!$F$2:$F$203) -> 15809.698 | F23: p50 units-sorted (p25 was above band)
A24: Total | B24: =SUM(B2:B23) -> 202 | C24: =SUM(C2:C23) -> 163 | D24: =SUM(D2:D23) -> 44
A25: Shoes | B25: 0 | C25: 0 | D25: 0 | F25: Checked one page – still above £30K; band is deeper (not reached on trial credits)
A26: Luggage & Bags | B26: 0 | C26: 0 | D26: 0 | F26: Checked one page – still above £30K; band is deeper (not reached on trial credits)
A27: Furniture | B27: 0 | C27: 0 | D27: 0 | F27: Checked one page – still above £30K; band is deeper (not reached on trial credits)
